# 关于try/catch块中return的使用

## 在try catch中使用return

当在`try`块中使用`return`语句时，它会立即终止当前函数的执行并返回一个值。这意味着`try`块中后续的代码将不会被执行。

如果在`try`块中使用`return`语句并指定了一个返回值，该返回值将成为整个函数的返回值。

在使用`try...catch`块时，`catch`块用于捕获`try`块中的异常。如果在`catch`块中使用`return`语句并指定一个返回值，该返回值将成为整个函数的返回值。这可以用于处理异常情况并返回一个特定的值或执行特定的逻辑。

以下是一个示例：

```javascript
function divide(a, b) {
  try {
    if (b === 0) {
      throw new Error('Divisor cannot be zero');
    }

    return a / b;
  } catch (error) {
    console.log('Error:', error.message);
    return null; // 在异常情况下返回null
  }
}

console.log(divide(10, 2));  // 输出: 5
console.log(divide(10, 0));  // 输出: Error: Divisor cannot be zero \n null
```

在这个示例中，`divide`函数用于计算两个数的商。如果除数`b`为零，会抛出一个异常，并在`catch`块中处理该异常并返回`null`作为函数的返回值。

使用`return`语句可以在适当的时候提前终止函数的执行，并返回一个特定的值。这在异常处理和控制函数流程时非常有用。

## 在嵌套try catch中使用return

当在内部的`try`块中使用`return`语句时，它会立即终止当前内部`try`块的执行，并返回一个值。该返回值会被传递给包含内部`try...catch`结构的外部`catch`块。

在使用嵌套的`try...catch`结构时，外部的`catch`块用于捕获内部`try`块中的异常。如果在外部的`catch`块中使用`return`语句并指定一个返回值，该返回值会成为整个嵌套结构的最终返回值。

以下是一个示例：

```javascript
function divide(a, b) {
  try {
    try {
      if (b === 0) {
        throw new Error('Divisor cannot be zero');
      }

      return a / b;
    } catch (error) {
      console.log('Inner Error:', error.message);
      throw error; // 抛出内部异常，将在外部的catch块中处理
    }
  } catch (error) {
    console.log('Outer Error:', error.message);
    return null; // 在外部的异常情况下返回null
  }
}

console.log(divide(10, 2));  // 输出: 5
console.log(divide(10, 0));  // 输出: Inner Error: Divisor cannot be zero \n Outer Error: Divisor cannot be zero \n null
```

在这个示例中，`divide`函数嵌套了两层`try...catch`结构。在内部的`try`块中，如果除数`b`为零，会抛出一个异常，并在内部的`catch`块中处理该异常并重新抛出。外部的`catch`块用于捕获内部`try`块中的异常，并在外部处理异常情况。

在异常情况下，最内部的异常被捕获并传递给外部的`catch`块，然后在外部的`catch`块中执行相应的逻辑，并返回`null`作为最终的返回值。

使用`return`语句可以在适当的时候提前终止函数的执行，并返回一个特定的值。在嵌套的`try...catch`结构中，内部的`return`语句可以影响外部的`catch`块的执行和最终的返回值。